[2025-07-28 23:11:32,801] [ERROR] ARC - Erreur pendant le calcul
Traceback (most recent call last):
  File "/home/frantz/ARC-autonomous-risk-coverage/backend/app.py", line 31, in calculate_risk
    from utils.risk import get_weather_data
ImportError: cannot import name 'get_weather_data' from 'utils.risk' (/home/frantz/ARC-autonomous-risk-coverage/backend/utils/risk.py)
